"""Tests for error recovery mechanisms."""

from typing import Any
from unittest.mock import patch

import pytest

from ti4.core.exceptions import TI4GameError


class TestErrorRecoveryMechanisms:
    """Test error recovery mechanisms for different failure types."""

    def test_graceful_degradation_for_non_critical_failures(self) -> None:
        """Test graceful degradation when non-critical operations fail."""
        # RED: This will fail because ErrorRecoveryManager doesn't exist yet
        from ti4.core.error_recovery import ErrorRecoveryManager

        recovery_manager = ErrorRecoveryManager()

        # Mock a non-critical operation that fails
        def failing_operation() -> None:
            raise TI4GameError("Non-critical operation failed")

        def fallback_operation() -> None:
            return "fallback_result"

        # Should gracefully degrade to fallback
        result = recovery_manager.execute_with_fallback(
            failing_operation, fallback_operation, is_critical=False
        )

        assert result == "fallback_result"

    def test_automatic_retry_for_transient_errors(self) -> None:
        """Test automatic retry mechanism for transient errors."""
        # RED: This will fail because ErrorRecoveryManager doesn't exist yet
        from ti4.core.error_recovery import ErrorRecoveryManager, TransientError

        recovery_manager = ErrorRecoveryManager()

        # Mock operation that fails twice then succeeds
        call_count = 0

        def flaky_operation() -> None:
            nonlocal call_count
            call_count += 1
            if call_count < 3:
                raise TransientError("Temporary failure")
            return "success"

        result = recovery_manager.execute_with_retry(
            flaky_operation, max_retries=3, retry_delay=0.01
        )

        assert result == "success"
        assert call_count == 3

    def test_retry_exhaustion_raises_original_error(self) -> None:
        """Test that retry exhaustion raises the original error."""
        # RED: This will fail because ErrorRecoveryManager doesn't exist yet
        from ti4.core.error_recovery import ErrorRecoveryManager, TransientError

        recovery_manager = ErrorRecoveryManager()

        def always_failing_operation() -> None:
            raise TransientError("Always fails")

        with pytest.raises(TransientError, match="Always fails"):
            recovery_manager.execute_with_retry(
                always_failing_operation, max_retries=2, retry_delay=0.01
            )

    def test_circuit_breaker_for_repeated_failures(self) -> None:
        """Test circuit breaker pattern for repeated failures."""
        # RED: This will fail because ErrorRecoveryManager doesn't exist yet
        from ti4.core.error_recovery import (
            CircuitBreakerOpenError,
            ErrorRecoveryManager,
        )

        recovery_manager = ErrorRecoveryManager()

        def failing_operation() -> None:
            raise TI4GameError("Operation failed")

        # First few failures should be attempted
        for _ in range(3):
            with pytest.raises(TI4GameError):
                recovery_manager.execute_with_circuit_breaker(
                    failing_operation,
                    operation_id="test_operation",
                    failure_threshold=3,
                )

        # After threshold, circuit breaker should open
        with pytest.raises(CircuitBreakerOpenError):
            recovery_manager.execute_with_circuit_breaker(
                failing_operation, operation_id="test_operation", failure_threshold=3
            )

    def test_error_recovery_strategy_selection(self) -> None:
        """Test that appropriate recovery strategy is selected based on error type."""
        # RED: This will fail because ErrorRecoveryManager doesn't exist yet
        from ti4.core.error_recovery import ErrorRecoveryManager

        recovery_manager = ErrorRecoveryManager()

        # Register custom recovery strategy
        def custom_recovery_strategy(error: Exception, context: dict[str, Any]) -> Any:
            if isinstance(error, ValueError):
                return "recovered_from_value_error"
            raise error

        recovery_manager.register_recovery_strategy(
            ValueError, custom_recovery_strategy
        )

        def failing_operation() -> None:
            raise ValueError("Test error")

        result = recovery_manager.execute_with_recovery(failing_operation)
        assert result == "recovered_from_value_error"

    def test_recovery_context_preservation(self) -> None:
        """Test that recovery mechanisms preserve error context."""
        # RED: This will fail because ErrorRecoveryManager doesn't exist yet
        from ti4.core.error_recovery import ErrorRecoveryManager

        recovery_manager = ErrorRecoveryManager()

        original_context = {"game_id": "test_game", "player_id": "player_1"}

        def failing_operation() -> None:
            raise TI4GameError("Test error", context=original_context)

        def fallback_operation() -> None:
            return "fallback"

        # Recovery should preserve original error context
        with patch.object(recovery_manager, "_log_recovery") as mock_log:
            recovery_manager.execute_with_fallback(
                failing_operation, fallback_operation, is_critical=False
            )

            # Verify recovery was logged with original context
            mock_log.assert_called_once()
            logged_error = mock_log.call_args[0][0]
            assert logged_error.context == original_context
